<?xml version="1.0"?>
<!-- created with Phobos 1.0.1 "Capricious Choutengan" -->
  <robot name="Carausius_Morosus">

    <link name="01_Carput">
      <inertial>
        <origin xyz="0.00302 -0.22324 0.0006" rpy="0 0 0"/>
        <mass value="0.01734"/>
        <inertia ixx="0.1662" ixy="-0.0014" ixz="-0.00026" iyy="0.06765" iyz="-0.00439" izz="0.17188"/>
      </inertial>
      <visual name="01_Carput.001">
        <origin xyz="0.00302 -0.22324 0.0006" rpy="1.57079 -1.55593 -1.57079"/>
        <geometry>
          <mesh filename="../meshes/obj/Textured_mesh_1.obj" scale="1.0 1.0 1.0"/>
        </geometry>
        <material name="Textured_mesh_1"/>
      </visual>
      <collision name="01_Carput.001">
        <origin xyz="0.00708 -0.22508 -0.0019" rpy="1.57079 -1.55593 -1.57079"/>
        <geometry>
          <box size="0.2872 0.51114 0.26191"/>
        </geometry>
      </collision>
    </link>

    <link name="02_Prothorax">
      <inertial>
        <origin xyz="-0.02817 0.1821 -0.00079" rpy="0 0 0"/>
        <mass value="0.01652"/>
        <inertia ixx="0.11554" ixy="0.00076" ixz="0.00174" iyy="0.0888" iyz="-0.00078" izz="0.11237"/>
      </inertial>
      <visual name="02_Prothorax.001">
        <origin xyz="-0.02817 0.1821 -0.00079" rpy="1.57079 -1.55593 -1.57079"/>
        <geometry>
          <mesh filename="../meshes/obj/Textured_mesh_1.002.obj" scale="1.0 1.0 1.0"/>
        </geometry>
        <material name="Textured_mesh_1"/>
      </visual>
      <collision name="02_Prothorax.001">
        <origin xyz="-0.03242 0.16363 -0.00501" rpy="1.57079 -1.55593 -1.57079"/>
        <geometry>
          <box size="0.26856 0.3839 0.2771"/>
        </geometry>
      </collision>
    </link>

    <link name="03_Mesothorax">
      <inertial>
        <origin xyz="0.00159 0.83837 0.01605" rpy="0 0 0"/>
        <mass value="0.107"/>
        <inertia ixx="1.77335" ixy="0.04236" ixz="-0.00803" iyy="0.13748" iyz="-0.01507" izz="1.74369"/>
      </inertial>
      <visual name="03_Mesothorax.001">
        <origin xyz="0.00159 0.83837 0.01605" rpy="1.57079 -1.55593 -1.57079"/>
        <geometry>
          <mesh filename="../meshes/obj/Textured_mesh_1.015.obj" scale="1.0 1.0 1.0"/>
        </geometry>
        <material name="Textured_mesh_1"/>
      </visual>
      <collision name="03_Mesothorax.001">
        <origin xyz="-0.00525 0.74954 0.01072" rpy="1.57079 -1.55593 -1.57079"/>
        <geometry>
          <box size="0.35816 1.50299 0.41009"/>
        </geometry>
      </collision>
    </link>

    <link name="04_Metathorax">
      <inertial>
        <origin xyz="0.00926 0.49776 0.00344" rpy="0 0 0"/>
        <mass value="0.08129"/>
        <inertia ixx="0.75377" ixy="0.00097" ixz="0.00017" iyy="0.15483" iyz="-0.02163" izz="0.74457"/>
      </inertial>
      <visual name="04_Metathorax.001">
        <origin xyz="0.00926 0.49776 0.00344" rpy="1.57079 -1.55593 -1.57079"/>
        <geometry>
          <mesh filename="../meshes/obj/Textured_mesh_1.025.obj" scale="1.0 1.0 1.0"/>
        </geometry>
        <material name="Textured_mesh_1"/>
      </visual>
      <collision name="04_Metathorax.001">
        <origin xyz="0.0129 0.47632 -0.00101" rpy="1.57079 -1.55593 -1.57079"/>
        <geometry>
          <box size="0.35718 0.95917 0.40991"/>
        </geometry>
      </collision>
    </link>

    <link name="05_Abdomen3">
      <inertial>
        <origin xyz="0.04382 0.43454 0.01167" rpy="0 0 0"/>
        <mass value="0.08065"/>
        <inertia ixx="0.59224" ixy="0.00949" ixz="-0.00088" iyy="0.17472" iyz="-0.03459" izz="0.55314"/>
      </inertial>
      <visual name="05_Abdomen_3">
        <origin xyz="0.04382 0.43454 0.01167" rpy="1.57079 -1.55593 -1.57079"/>
        <geometry>
          <mesh filename="../meshes/obj/Textured_mesh_1.024.obj" scale="1.0 1.0 1.0"/>
        </geometry>
        <material name="Textured_mesh_1"/>
      </visual>
      <collision name="05_Abdomen_3">
        <origin xyz="0.05205 0.41978 0.01016" rpy="1.57079 -1.55593 -1.57079"/>
        <geometry>
          <box size="0.34948 0.84643 0.44251"/>
        </geometry>
      </collision>
    </link>

    <link name="06_Abdomen2">
      <inertial>
        <origin xyz="0.00602 0.4457 0.01063" rpy="0 0 0"/>
        <mass value="0.07952"/>
        <inertia ixx="0.68571" ixy="0.01524" ixz="0.0201" iyy="0.16045" iyz="-0.01983" izz="0.64362"/>
      </inertial>
      <visual name="06_Abdomen_2">
        <origin xyz="0.00602 0.4457 0.01063" rpy="1.57079 -1.55593 -1.57079"/>
        <geometry>
          <mesh filename="../meshes/obj/Textured_mesh_1.035.obj" scale="1.0 1.0 1.0"/>
        </geometry>
        <material name="Textured_mesh_1"/>
      </visual>
      <collision name="06_Abdomen_2">
        <origin xyz="0.01018 0.46023 0.01352" rpy="1.57079 -1.55593 -1.57079"/>
        <geometry>
          <box size="0.35343 0.92509 0.42333"/>
        </geometry>
      </collision>
    </link>

    <link name="07_Abdomen1">
      <inertial>
        <origin xyz="-0.0041 0.37345 -0.00983" rpy="0 0 0"/>
        <mass value="0.05407"/>
        <inertia ixx="0.49468" ixy="0.0137" ixz="0.01486" iyy="0.12353" iyz="-0.00338" izz="0.47956"/>
      </inertial>
      <visual name="07_Abdomen_1">
        <origin xyz="-0.0041 0.37345 -0.00983" rpy="1.57079 -1.55593 -1.57079"/>
        <geometry>
          <mesh filename="../meshes/obj/Textured_mesh_1.036.obj" scale="1.0 1.0 1.0"/>
        </geometry>
        <material name="Textured_mesh_1"/>
      </visual>
      <collision name="07_Abdomen_1">
        <origin xyz="-0.00216 0.39871 -0.00674" rpy="1.57079 -1.55593 -1.57079"/>
        <geometry>
          <box size="0.33276 0.80331 0.37792"/>
        </geometry>
      </collision>
    </link>

    <link name="08_Abdomen0">
      <inertial>
        <origin xyz="-0.02911 0.35459 -0.00595" rpy="0 0 0"/>
        <mass value="0.04623"/>
        <inertia ixx="0.41934" ixy="0.01203" ixz="0.01243" iyy="0.14055" iyz="0.04519" izz="0.36393"/>
      </inertial>
      <visual name="08_Abdomen_0">
        <origin xyz="-0.02911 0.35459 -0.00595" rpy="1.57079 -1.55593 -1.57079"/>
        <geometry>
          <mesh filename="../meshes/obj/Textured_mesh_1.037.obj" scale="1.0 1.0 1.0"/>
        </geometry>
        <material name="Textured_mesh_1"/>
      </visual>
      <collision name="08_Abdomen_0">
        <origin xyz="-0.02105 0.35704 -0.00926" rpy="1.57079 -1.55593 -1.57079"/>
        <geometry>
          <box size="0.31676 0.7175 0.36188"/>
        </geometry>
      </collision>
    </link>

    <link name="09_CT_HL_L">
      <inertial>
        <origin xyz="0.04633 0.00356 0.01054" rpy="0 0 0"/>
        <mass value="0.00105"/>
        <inertia ixx="0.01863" ixy="0" ixz="-0.00063" iyy="0.01893" iyz="-0.00158" izz="0.01407"/>
      </inertial>
      <visual name="HL_CT_L">
        <origin xyz="0.04633 0.00356 0.01054" rpy="0 0 -0.01487"/>
        <geometry>
          <mesh filename="../meshes/obj/Textured_mesh_1.013.obj" scale="1.0 1.0 1.0"/>
        </geometry>
        <material name="Textured_mesh_1"/>
      </visual>
      <collision name="HL_CT_L">
        <origin xyz="0.05575 0.00274 0.00927" rpy="0 0 -0.01487"/>
        <geometry>
          <box size="0.11438 0.11821 0.15527"/>
        </geometry>
      </collision>
    </link>

    <link name="10_Femur_HL_L">
      <inertial>
        <origin xyz="0.65172 0.00558 0.00198" rpy="0 0 0"/>
        <mass value="0.0045"/>
        <inertia ixx="0.00956" ixy="-0.01522" ixz="0.01542" iyy="1.33345" iyz="-0.00206" izz="1.33152"/>
      </inertial>
      <visual name="HL_Femur_L">
        <origin xyz="0.65172 0.00558 0.00198" rpy="-1.5708 -0.01487 0"/>
        <geometry>
          <mesh filename="../meshes/obj/Textured_mesh_1.027.obj" scale="1.0 1.0 1.0"/>
        </geometry>
        <material name="Textured_mesh_1"/>
      </visual>
      <collision name="HL_Femur_L">
        <origin xyz="0.62626 0.00719 -0.00451" rpy="-1.5708 -0.01487 0"/>
        <geometry>
          <box size="1.2533 0.10548 0.12222"/>
        </geometry>
      </collision>
    </link>

    <link name="11_Tibia_HL_L">
      <inertial>
        <origin xyz="0.00266 -0.6868 0.00147" rpy="0 0 0"/>
        <mass value="0.00283"/>
        <inertia ixx="2.041" ixy="0.0027" ixz="0.02947" iyy="2.04199" iyz="0.0181" izz="0.00457"/>
      </inertial>
      <visual name="HL_Tibia_L">
        <origin xyz="0.00266 -0.6868 0.00147" rpy="-1.5708 -0.01487 0"/>
        <geometry>
          <mesh filename="../meshes/obj/Textured_mesh_1.029.obj" scale="1.0 1.0 1.0"/>
        </geometry>
        <material name="Textured_mesh_1"/>
      </visual>
      <collision name="HL_Tibia_L">
        <origin xyz="0.00385 -0.72465 -0.00246" rpy="-1.5708 -0.01487 0"/>
        <geometry>
          <box size="0.07513 0.0739 1.51698"/>
        </geometry>
      </collision>
    </link>

    <link name="12_Tarsus_HL_L">
      <inertial>
        <origin xyz="0.20162 -0.00337 -0.00149" rpy="0 0 0"/>
        <mass value="0.00053"/>
        <inertia ixx="0.00406" ixy="0.003" ixz="0.00352" iyy="0.11349" iyz="0.0003" izz="0.11343"/>
      </inertial>
      <visual name="HL_Pretarsus_L">
        <origin xyz="0.20162 -0.00337 -0.00149" rpy="-1.5708 -0.01487 0"/>
        <geometry>
          <mesh filename="../meshes/obj/Textured_mesh_1.030.obj" scale="1.0 1.0 1.0"/>
        </geometry>
        <material name="Textured_mesh_1"/>
      </visual>
      <collision name="HL_Pretarsus_L">
        <origin xyz="0.17312 0.01729 -0.01411" rpy="-1.5708 -0.01487 0"/>
        <geometry>
          <box size="0.3786 0.09449 0.09233"/>
        </geometry>
      </collision>
    </link>

    <link name="13_CT_HL_R">
      <inertial>
        <origin xyz="-0.05642 -0.00251 0.00191" rpy="0 0 0"/>
        <mass value="0.00138"/>
        <inertia ixx="0.0206" ixy="-0.00167" ixz="0.00025" iyy="0.02528" iyz="0" izz="0.01786"/>
      </inertial>
      <visual name="HL_CT_R">
        <origin xyz="-0.05642 -0.00251 0.00191" rpy="0 0 -0.01487"/>
        <geometry>
          <mesh filename="../meshes/obj/Textured_mesh_1.026.obj" scale="1.0 1.0 1.0"/>
        </geometry>
        <material name="Textured_mesh_1"/>
      </visual>
      <collision name="HL_CT_R">
        <origin xyz="-0.06944 -0.0095 0.00277" rpy="0 0 -0.01487"/>
        <geometry>
          <box size="0.1411 0.12043 0.16756"/>
        </geometry>
      </collision>
    </link>

    <link name="14_Femur_HL_R">
      <inertial>
        <origin xyz="-0.67627 -0.02126 0.00547" rpy="0 0 0"/>
        <mass value="0.00458"/>
        <inertia ixx="0.01013" ixy="-0.03408" ixz="-0.00308" iyy="1.44455" iyz="-0.00046" izz="1.4404"/>
      </inertial>
      <visual name="HL_Femur_R">
        <origin xyz="-0.67627 -0.02126 0.00547" rpy="-1.5708 -0.01487 0"/>
        <geometry>
          <mesh filename="../meshes/obj/Textured_mesh_1.031.obj" scale="1.0 1.0 1.0"/>
        </geometry>
        <material name="Textured_mesh_1"/>
      </visual>
      <collision name="HL_Femur_R">
        <origin xyz="-0.63805 -0.01903 0.00328" rpy="-1.5708 -0.01487 0"/>
        <geometry>
          <box size="1.27697 0.08758 0.1209"/>
        </geometry>
      </collision>
    </link>

    <link name="15_Tibia_HL_R">
      <inertial>
        <origin xyz="0.00874 -0.62706 -0.00339" rpy="0 0 0"/>
        <mass value="0.00199"/>
        <inertia ixx="1.58682" ixy="-0.02014" ixz="0.02353" iyy="1.58492" iyz="0.01755" izz="0.0046"/>
      </inertial>
      <visual name="HL_Tibia_R">
        <origin xyz="0.00874 -0.62705 -0.00339" rpy="-1.5708 -0.01487 0"/>
        <geometry>
          <mesh filename="../meshes/obj/Textured_mesh_1.033.obj" scale="1.0 1.0 1.0"/>
        </geometry>
        <material name="Textured_mesh_1"/>
      </visual>
      <collision name="HL_Tibia_R">
        <origin xyz="0.00193 -0.63238 -0.00535" rpy="-1.5708 -0.01487 0"/>
        <geometry>
          <box size="0.07538 0.07884 1.32637"/>
        </geometry>
      </collision>
    </link>

    <link name="16_Tarsus_HL_R">
      <inertial>
        <origin xyz="-0.28352 -0.00363 0.00364" rpy="0 0 0"/>
        <mass value="0.00072"/>
        <inertia ixx="0.00476" ixy="-0.01343" ixz="-0.00409" iyy="0.22983" iyz="-0.00017" izz="0.23124"/>
      </inertial>
      <visual name="HL_Tarsus_R">
        <origin xyz="-0.28352 -0.00363 0.00364" rpy="-1.5708 -0.01487 0"/>
        <geometry>
          <mesh filename="../meshes/obj/Textured_mesh_1.032.obj" scale="1.0 1.0 1.0"/>
        </geometry>
        <material name="Textured_mesh_1"/>
      </visual>
      <collision name="HL_Tarsus_R">
        <origin xyz="-0.24205 0.00839 -0.00449" rpy="-1.5708 -0.01487 0"/>
        <geometry>
          <box size="0.54248 0.09576 0.06815"/>
        </geometry>
      </collision>
    </link>

    <link name="17_CT_ML_L">
      <inertial>
        <origin xyz="0.04972 0.00469 -0.00707" rpy="0 0 0"/>
        <mass value="0.00088"/>
        <inertia ixx="0.01467" ixy="2e-05" ixz="0.00055" iyy="0.01776" iyz="0.00102" izz="0.01519"/>
      </inertial>
      <visual name="ML_CT_L">
        <origin xyz="0.04972 0.00469 -0.00707" rpy="0 0 -0.01487"/>
        <geometry>
          <mesh filename="../meshes/obj/Textured_mesh_1.007.obj" scale="1.0 1.0 1.0"/>
        </geometry>
        <material name="Textured_mesh_1"/>
      </visual>
      <collision name="ML_CT_L">
        <origin xyz="0.06135 -0.0025 -0.00601" rpy="0 0 -0.01487"/>
        <geometry>
          <box size="0.12498 0.12881 0.13426"/>
        </geometry>
      </collision>
    </link>

    <link name="18_Femur_ML_L">
      <inertial>
        <origin xyz="0.54614 -0.0171 0.01253" rpy="0 0 0"/>
        <mass value="0.00457"/>
        <inertia ixx="0.01143" ixy="-0.02923" ixz="-0.02402" iyy="0.83123" iyz="0.00153" izz="0.83209"/>
      </inertial>
      <visual name="ML_Femur_L">
        <origin xyz="0.54613 -0.0171 0.01253" rpy="-1.5708 -0.01487 0"/>
        <geometry>
          <mesh filename="../meshes/obj/Textured_mesh_1.021.obj" scale="1.0 1.0 1.0"/>
        </geometry>
        <material name="Textured_mesh_1"/>
      </visual>
      <collision name="ML_Femur_L">
        <origin xyz="0.52305 -0.01435 0.01803" rpy="-1.5708 -0.01487 0"/>
        <geometry>
          <box size="1.04842 0.12186 0.10541"/>
        </geometry>
      </collision>
    </link>

    <link name="19_Tibia_ML_L">
      <inertial>
        <origin xyz="0.012 -0.53481 -0.0085" rpy="0 0 0"/>
        <mass value="0.00144"/>
        <inertia ixx="1.1539" ixy="-0.02167" ixz="0.01662" iyy="1.15215" iyz="0.01802" izz="0.00371"/>
      </inertial>
      <visual name="ML_Tibia_L">
        <origin xyz="0.012 -0.53481 -0.0085" rpy="-1.5708 -0.01487 0"/>
        <geometry>
          <mesh filename="../meshes/obj/Textured_mesh_1.022.obj" scale="1.0 1.0 1.0"/>
        </geometry>
        <material name="Textured_mesh_1"/>
      </visual>
      <collision name="ML_Tibia_L">
        <origin xyz="0.00937 -0.5588 -0.00809" rpy="-1.5708 -0.01487 0"/>
        <geometry>
          <box size="0.07714 0.07635 1.16387"/>
        </geometry>
      </collision>
    </link>

    <link name="20_Tarsus_ML_L">
      <inertial>
        <origin xyz="0.16622 -0.00569 -0.00268" rpy="0 0 0"/>
        <mass value="0.00034"/>
        <inertia ixx="0.00317" ixy="0.00312" ixz="-0.00076" iyy="0.08032" iyz="6e-05" izz="0.08032"/>
      </inertial>
      <visual name="ML_Pretarsus_L">
        <origin xyz="0.16622 -0.00569 -0.00268" rpy="-1.5708 -0.01487 0"/>
        <geometry>
          <mesh filename="../meshes/obj/Textured_mesh_1.020.obj" scale="1.0 1.0 1.0"/>
        </geometry>
        <material name="Textured_mesh_1"/>
      </visual>
      <collision name="ML_Pretarsus_L">
        <origin xyz="0.14281 0.00743 -0.0049" rpy="-1.5708 -0.01487 0"/>
        <geometry>
          <box size="0.31035 0.09309 0.06525"/>
        </geometry>
      </collision>
    </link>

    <link name="21_CT_ML_R">
      <inertial>
        <origin xyz="-0.04743 0.00203 -0.00144" rpy="0 0 0"/>
        <mass value="0.00084"/>
        <inertia ixx="0.01426" ixy="3e-05" ixz="8e-05" iyy="0.01666" iyz="-0.0002" izz="0.01302"/>
      </inertial>
      <visual name="ML_CT_R">
        <origin xyz="-0.04743 0.00203 -0.00144" rpy="0 0 -0.01487"/>
        <geometry>
          <mesh filename="../meshes/obj/Textured_mesh_1.014.obj" scale="1.0 1.0 1.0"/>
        </geometry>
        <material name="Textured_mesh_1"/>
      </visual>
      <collision name="ML_CT_R">
        <origin xyz="-0.05988 -0.00118 -0.00148" rpy="0 0 -0.01487"/>
        <geometry>
          <box size="0.12142 0.10543 0.14525"/>
        </geometry>
      </collision>
    </link>

    <link name="22_Femur_ML_R">
      <inertial>
        <origin xyz="-0.54018 -0.00117 0.00782" rpy="0 0 0"/>
        <mass value="0.00383"/>
        <inertia ixx="0.01261" ixy="-0.05352" ixz="0.00965" iyy="0.81566" iyz="0.00076" izz="0.81295"/>
      </inertial>
      <visual name="ML_Femur_R">
        <origin xyz="-0.54018 -0.00117 0.00782" rpy="-1.5708 -0.01487 0"/>
        <geometry>
          <mesh filename="../meshes/obj/Textured_mesh_1.016.obj" scale="1.0 1.0 1.0"/>
        </geometry>
        <material name="Textured_mesh_1"/>
      </visual>
      <collision name="ML_Femur_R">
        <origin xyz="-0.51648 0.0059 0.00798" rpy="-1.5708 -0.01487 0"/>
        <geometry>
          <box size="1.03374 0.09225 0.13447"/>
        </geometry>
      </collision>
    </link>

    <link name="23_Tibia_ML_R">
      <inertial>
        <origin xyz="-0.00327 -0.49428 0.00175" rpy="0 0 0"/>
        <mass value="0.00149"/>
        <inertia ixx="0.95216" ixy="0.00466" ixz="0.01482" iyy="0.95324" iyz="-0.01118" izz="0.00354"/>
      </inertial>
      <visual name="ML_Tibia_R">
        <origin xyz="-0.00327 -0.49428 0.00175" rpy="-1.5708 -0.01487 0"/>
        <geometry>
          <mesh filename="../meshes/obj/Textured_mesh_1.018.obj" scale="1.0 1.0 1.0"/>
        </geometry>
        <material name="Textured_mesh_1"/>
      </visual>
      <collision name="ML_Tibia_R">
        <origin xyz="-0.00272 -0.49963 0.00156" rpy="-1.5708 -0.01487 0"/>
        <geometry>
          <box size="0.07381 0.06888 1.05127"/>
        </geometry>
      </collision>
    </link>

    <link name="24_Tarsus_ML_R">
      <inertial>
        <origin xyz="-0.22467 -0.00926 -0.00531" rpy="0 0 0"/>
        <mass value="0.0005"/>
        <inertia ixx="0.00418" ixy="-0.0101" ixz="0.00572" iyy="0.15275" iyz="0.00035" izz="0.15446"/>
      </inertial>
      <visual name="ML_Tarsus_R">
        <origin xyz="-0.22467 -0.00926 -0.00531" rpy="-1.5708 -0.01487 0"/>
        <geometry>
          <mesh filename="../meshes/obj/Textured_mesh_1.017.obj" scale="1.0 1.0 1.0"/>
        </geometry>
        <material name="Textured_mesh_1"/>
      </visual>
      <collision name="ML_Tarsus_R">
        <origin xyz="-0.20296 0.00959 0.00779" rpy="-1.5708 -0.01487 0"/>
        <geometry>
          <box size="0.43172 0.09934 0.07049"/>
        </geometry>
      </collision>
    </link>

    <link name="25_CT_FL_L">
      <inertial>
        <origin xyz="0.05478 0.01692 -0.00968" rpy="0 0 0"/>
        <mass value="0.00128"/>
        <inertia ixx="0.02061" ixy="0.00144" ixz="-0.00138" iyy="0.02243" iyz="0.00073" izz="0.0194"/>
      </inertial>
      <visual name="FL_CT_L">
        <origin xyz="0.05478 0.01692 -0.00968" rpy="0 0 -0.01487"/>
        <geometry>
          <mesh filename="../meshes/obj/Textured_mesh_1.001.obj" scale="1.0 1.0 1.0"/>
        </geometry>
        <material name="Textured_mesh_1"/>
      </visual>
      <collision name="FL_CT_L">
        <origin xyz="0.06118 0.00576 0.00327" rpy="0 0 -0.01487"/>
        <geometry>
          <box size="0.12806 0.14832 0.16339"/>
        </geometry>
      </collision>
    </link>

    <link name="26_Femur_FL_L">
      <inertial>
        <origin xyz="0.79451 0.01004 0.00657" rpy="0 0 0"/>
        <mass value="0.00669"/>
        <inertia ixx="0.01212" ixy="-0.02424" ixz="-0.00902" iyy="1.7984" iyz="0.00087" izz="1.79809"/>
      </inertial>
      <visual name="FL_Femur_L">
        <origin xyz="0.79451 0.01004 0.00657" rpy="-1.5708 -0.01487 0"/>
        <geometry>
          <mesh filename="../meshes/obj/Textured_mesh_1.004.obj" scale="1.0 1.0 1.0"/>
        </geometry>
        <material name="Textured_mesh_1"/>
      </visual>
      <collision name="FL_Femur_L">
        <origin xyz="0.71911 0.00861 0.00699" rpy="-1.5708 -0.01487 0"/>
        <geometry>
          <box size="1.4398 0.14697 0.13196"/>
        </geometry>
      </collision>
    </link>

    <link name="27_Tibia_FL_L">
      <inertial>
        <origin xyz="-0.01049 -0.47366 -0.01205" rpy="0 0 0"/>
        <mass value="0.00209"/>
        <inertia ixx="1.31703" ixy="0.01067" ixz="0.01669" iyy="1.32013" iyz="0.00419" izz="0.00964"/>
      </inertial>
      <visual name="FL_Tibia_L">
        <origin xyz="-0.01049 -0.47366 -0.01205" rpy="-1.5708 -0.01487 0"/>
        <geometry>
          <mesh filename="../meshes/obj/Textured_mesh_1.005.obj" scale="1.0 1.0 1.0"/>
        </geometry>
        <material name="Textured_mesh_1"/>
      </visual>
      <collision name="FL_Tibia_L">
        <origin xyz="0.00132 -0.63387 0.00093" rpy="-1.5708 -0.01487 0"/>
        <geometry>
          <box size="0.12238 0.08635 1.35634"/>
        </geometry>
      </collision>
    </link>

    <link name="28_Tarsus_FL_L">
      <inertial>
        <origin xyz="0.18427 -0.00028 -0.00057" rpy="0 0 0"/>
        <mass value="0.00045"/>
        <inertia ixx="0.00315" ixy="0.00197" ixz="-0.00155" iyy="0.10112" iyz="-0.00015" izz="0.09981"/>
      </inertial>
      <visual name="FL_Pretarsus_L">
        <origin xyz="0.18427 -0.00028 -0.00057" rpy="-1.5708 -0.01487 0"/>
        <geometry>
          <mesh filename="../meshes/obj/Textured_mesh_1.006.obj" scale="1.0 1.0 1.0"/>
        </geometry>
        <material name="Textured_mesh_1"/>
      </visual>
      <collision name="FL_Pretarsus_L">
        <origin xyz="0.16 0.02264 0.00333" rpy="-1.5708 -0.01487 0"/>
        <geometry>
          <box size="0.34782 0.06236 0.08457"/>
        </geometry>
      </collision>
    </link>

    <link name="29_CT_FL_R">
      <inertial>
        <origin xyz="-0.04664 0.00159 -0.00418" rpy="0 0 0"/>
        <mass value="0.00088"/>
        <inertia ixx="0.01574" ixy="-0.00059" ixz="-0.00061" iyy="0.01661" iyz="-0.00123" izz="0.01362"/>
      </inertial>
      <visual name="FL_CT_R">
        <origin xyz="-0.04664 0.00159 -0.00418" rpy="0 0 -0.01487"/>
        <geometry>
          <mesh filename="../meshes/obj/Textured_mesh_1.008.obj" scale="1.0 1.0 1.0"/>
        </geometry>
        <material name="Textured_mesh_1"/>
      </visual>
      <collision name="FL_CT_R">
        <origin xyz="-0.05323 0.00316 -0.00253" rpy="0 0 -0.01487"/>
        <geometry>
          <box size="0.10794 0.11094 0.14077"/>
        </geometry>
      </collision>
    </link>

    <link name="30_Femur_FL_R">
      <inertial>
        <origin xyz="-0.76848 0.00756 0.02874" rpy="0 0 0"/>
        <mass value="0.0062"/>
        <inertia ixx="0.01504" ixy="-0.06688" ixz="0.01174" iyy="1.48441" iyz="0.00155" izz="1.48958"/>
      </inertial>
      <visual name="FL_Femur_R">
        <origin xyz="-0.76848 0.00756 0.02874" rpy="-1.5708 -0.01487 0"/>
        <geometry>
          <mesh filename="../meshes/obj/Textured_mesh_1.010.obj" scale="1.0 1.0 1.0"/>
        </geometry>
        <material name="Textured_mesh_1"/>
      </visual>
      <collision name="FL_Femur_R">
        <origin xyz="-0.71363 0.00665 0.0329" rpy="-1.5708 -0.01487 0"/>
        <geometry>
          <box size="1.42725 0.15388 0.12"/>
        </geometry>
      </collision>
    </link>

    <link name="31_Tibia_FL_R">
      <inertial>
        <origin xyz="-0.01295 -0.63875 0.0059" rpy="0 0 0"/>
        <mass value="0.00264"/>
        <inertia ixx="1.76933" ixy="0.00997" ixz="0.02497" iyy="1.77008" iyz="0.03958" izz="0.00661"/>
      </inertial>
      <visual name="FL_Tibia_R">
        <origin xyz="-0.01295 -0.63875 0.0059" rpy="-1.5708 -0.01487 0"/>
        <geometry>
          <mesh filename="../meshes/obj/Textured_mesh_1.011.obj" scale="1.0 1.0 1.0"/>
        </geometry>
        <material name="Textured_mesh_1"/>
      </visual>
      <collision name="FL_Tibia_R">
        <origin xyz="-0.00786 -0.69918 -0.00368" rpy="-1.5708 -0.01487 0"/>
        <geometry>
          <box size="0.10207 0.09593 1.45689"/>
        </geometry>
      </collision>
    </link>

    <link name="32_Tarsus_FL_R">
      <inertial>
        <origin xyz="-0.18964 -0.00375 0.00265" rpy="0 0 0"/>
        <mass value="0.00044"/>
        <inertia ixx="0.00354" ixy="-0.00731" ixz="0.00141" iyy="0.10417" iyz="-0.00015" izz="0.10364"/>
      </inertial>
      <visual name="FL_Tarsus_R">
        <origin xyz="-0.18964 -0.00375 0.00265" rpy="-1.5708 -0.01487 0"/>
        <geometry>
          <mesh filename="../meshes/obj/Textured_mesh_1.009.obj" scale="1.0 1.0 1.0"/>
        </geometry>
        <material name="Textured_mesh_1"/>
      </visual>
      <collision name="FL_Tarsus_R">
        <origin xyz="-0.16022 0.01366 0.00995" rpy="-1.5708 -0.01487 0"/>
        <geometry>
          <box size="0.35289 0.06335 0.08457"/>
        </geometry>
      </collision>
    </link>

    <joint name="02_Prothorax" type="revolute">
      <origin xyz="0 0 0" rpy="0 0 0"/>
      <parent link="01_Carput"/>
      <child link="02_Prothorax"/>
      <axis xyz="0 0 1.0"/>
      <limit lower="-1.0" upper="1.0" effort="0.05" velocity="5.0"/>
    </joint>

    <joint name="03_Mesothorax" type="revolute">
      <origin xyz="-0.03655 0.35385 0.00516" rpy="0 0 0"/>
      <parent link="02_Prothorax"/>
      <child link="03_Mesothorax"/>
      <axis xyz="0 0 1.0"/>
      <limit lower="-1.0" upper="1.0" effort="0.05" velocity="5.0"/>
    </joint>

    <joint name="04_Metathorax" type="revolute">
      <origin xyz="-0.03062 1.49945 0.0154" rpy="0 0 0"/>
      <parent link="03_Mesothorax"/>
      <child link="04_Metathorax"/>
      <axis xyz="0 0 1.0"/>
      <limit lower="-1.0" upper="1.0" effort="0.05" velocity="5.0"/>
    </joint>

    <joint name="05_Abdomen3" type="revolute">
      <origin xyz="-0.03293 0.95183 -0.01588" rpy="0 0 0"/>
      <parent link="04_Metathorax"/>
      <child link="05_Abdomen3"/>
      <axis xyz="0 0 1.0"/>
      <limit lower="-1.0" upper="1.0" effort="0.05" velocity="5.0"/>
    </joint>

    <joint name="06_Abdomen2" type="revolute">
      <origin xyz="0.05489 0.84056 0.00484" rpy="0 0 0"/>
      <parent link="05_Abdomen3"/>
      <child link="06_Abdomen2"/>
      <axis xyz="0 0 1.0"/>
      <limit lower="-1.0" upper="1.0" effort="0.05" velocity="5.0"/>
    </joint>

    <joint name="07_Abdomen1" type="revolute">
      <origin xyz="0.02255 0.92033 0.01897" rpy="0 0 0"/>
      <parent link="06_Abdomen2"/>
      <child link="07_Abdomen1"/>
      <axis xyz="0 0 1.0"/>
      <limit lower="-1.0" upper="1.0" effort="0.05" velocity="5.0"/>
    </joint>

    <joint name="08_Abdomen0" type="revolute">
      <origin xyz="-0.0067 0.79869 -0.02414" rpy="0 0 0"/>
      <parent link="07_Abdomen1"/>
      <child link="08_Abdomen0"/>
      <axis xyz="0 0 1.0"/>
      <limit lower="-1.0" upper="1.0" effort="0.05" velocity="5.0"/>
    </joint>

    <joint name="09_CT_HL_L" type="revolute">
      <origin xyz="0.12869 0.86509 0.17126" rpy="-1.57079 -1.55219 1.57079"/>
      <parent link="04_Metathorax"/>
      <child link="09_CT_HL_L"/>
      <axis xyz="0 0 1.0"/>
      <limit lower="-1.0" upper="1.0" effort="0.05" velocity="5.0"/>
    </joint>

    <joint name="10_Femur_HL_L" type="revolute">
      <origin xyz="0.11252 0.01067 0.00904" rpy="-0.59697 -1.54968 2.15569"/>
      <parent link="09_CT_HL_L"/>
      <child link="10_Femur_HL_L"/>
      <axis xyz="0 0 1.0"/>
      <limit lower="-1.0" upper="1.0" effort="0.05" velocity="5.0"/>
    </joint>

    <joint name="11_Tibia_HL_L" type="revolute">
      <origin xyz="1.22256 -0.00115 -0.00127" rpy="0.03004 0.00379 -1.4399"/>
      <parent link="10_Femur_HL_L"/>
      <child link="11_Tibia_HL_L"/>
      <axis xyz="0 0 1.0"/>
      <limit lower="-1.0" upper="1.0" effort="0.05" velocity="5.0"/>
    </joint>

    <joint name="12_Tarsus_HL_L" type="fixed">
      <origin xyz="0.00987 -1.4684 -0.00568" rpy="-0.01177 0.00401 -0.15613"/>
      <parent link="11_Tibia_HL_L"/>
      <child link="12_Tarsus_HL_L"/>
    </joint>

    <joint name="13_CT_HL_R" type="revolute">
      <origin xyz="0.06997 0.86687 -0.17293" rpy="1.5708 -0.7854 -1.5708"/>
      <parent link="04_Metathorax"/>
      <child link="13_CT_HL_R"/>
      <axis xyz="0 0 1.0"/>
      <limit lower="-1.0" upper="1.0" effort="0.05" velocity="5.0"/>
    </joint>

    <joint name="14_Femur_HL_R" type="revolute">
      <origin xyz="-0.13936 -0.00076 -0.00741" rpy="1.5708 0.49714 0"/>
      <parent link="13_CT_HL_R"/>
      <child link="14_Femur_HL_R"/>
      <axis xyz="0 0 1.0"/>
      <limit lower="-1.0" upper="1.0" effort="0.05" velocity="5.0"/>
    </joint>

    <joint name="15_Tibia_HL_R" type="revolute">
      <origin xyz="-1.24572 -0.05273 0.00429" rpy="0 0 0"/>
      <parent link="14_Femur_HL_R"/>
      <child link="15_Tibia_HL_R"/>
      <axis xyz="0 0 1.0"/>
      <limit lower="-1.0" upper="1.0" effort="0.05" velocity="5.0"/>
    </joint>

    <joint name="16_Tarsus_HL_R" type="fixed">
      <origin xyz="-0.01237 -1.27207 -0.00879" rpy="0 0 0.61847"/>
      <parent link="15_Tibia_HL_R"/>
      <child link="16_Tarsus_HL_R"/>
    </joint>

    <joint name="17_CT_ML_L" type="revolute">
      <origin xyz="0.07281 1.38866 0.19815" rpy="-1.5708 -1.0472 1.5708"/>
      <parent link="03_Mesothorax"/>
      <child link="17_CT_ML_L"/>
      <axis xyz="0 0 1.0"/>
      <limit lower="-1.0" upper="1.0" effort="0.05" velocity="5.0"/>
    </joint>

    <joint name="18_Femur_ML_L" type="revolute">
      <origin xyz="0.12335 0.00493 -0.0102" rpy="1.5708 -0.46182 0"/>
      <parent link="17_CT_ML_L"/>
      <child link="18_Femur_ML_L"/>
      <axis xyz="0 0 1.0"/>
      <limit lower="-1.0" upper="1.0" effort="500.0" velocity="100000000.0"/>
    </joint>

    <joint name="19_Tibia_ML_L" type="revolute">
      <origin xyz="1.02402 -0.03819 0.01027" rpy="0 0 -0.02841"/>
      <parent link="18_Femur_ML_L"/>
      <child link="19_Tibia_ML_L"/>
      <axis xyz="0 0 1.0"/>
      <limit lower="-1.0" upper="1.0" effort="0.05" velocity="5.0"/>
    </joint>

    <joint name="20_Tarsus_ML_L" type="fixed">
      <origin xyz="0.03066 -1.12653 -0.00892" rpy="-0.00938 0.0069 -0.37586"/>
      <parent link="19_Tibia_ML_L"/>
      <child link="20_Tarsus_ML_L"/>
    </joint>

    <joint name="21_CT_ML_R" type="revolute">
      <origin xyz="0.10923 1.40383 -0.14673" rpy="-1.57078 -1.56507 1.57078"/>
      <parent link="03_Mesothorax"/>
      <child link="21_CT_ML_R"/>
      <axis xyz="0 0 1.0"/>
      <limit lower="-1.0" upper="1.0" effort="0.05" velocity="5.0"/>
    </joint>

    <joint name="22_Femur_ML_R" type="revolute">
      <origin xyz="-0.11996 0.00201 -0.00162" rpy="1.22195 1.58592 -0.35207"/>
      <parent link="21_CT_ML_R"/>
      <child link="22_Femur_ML_R"/>
      <axis xyz="0 0 1.0"/>
      <limit lower="-1.0" upper="1.0" effort="0.05" velocity="5.0"/>
    </joint>

    <joint name="23_Tibia_ML_R" type="revolute">
      <origin xyz="-1.00334 0.00058 0.01466" rpy="-0.0061 0.00169 1.31469"/>
      <parent link="22_Femur_ML_R"/>
      <child link="23_Tibia_ML_R"/>
      <axis xyz="0 0 1.0"/>
      <limit lower="-1.0" upper="1.0" effort="0.05" velocity="5.0"/>
    </joint>

    <joint name="24_Tarsus_ML_R" type="fixed">
      <origin xyz="-0.02313 -1.01451 0.00158" rpy="0 0 0.26404"/>
      <parent link="23_Tibia_ML_R"/>
      <child link="24_Tarsus_ML_R"/>
    </joint>

    <joint name="25_CT_FL_L" type="floating">
      <origin xyz="0.01679 0.13779 0.12265" rpy="0 -1.5708 0"/>
      <parent link="02_Prothorax"/>
      <child link="25_CT_FL_L"/>
      <limit effort="0.05" velocity="5.0"/>
    </joint>

    <joint name="26_Femur_FL_L" type="revolute">
      <origin xyz="0.12467 0.01607 -0.01596" rpy="1.5708 -1.56671 0"/>
      <parent link="25_CT_FL_L"/>
      <child link="26_Femur_FL_L"/>
      <axis xyz="0 0 1.0"/>
      <limit lower="-1.0" upper="1.0" effort="0.05" velocity="5.0"/>
    </joint>

    <joint name="27_Tibia_FL_L" type="revolute">
      <origin xyz="1.39534 -0.00553 -0.00879" rpy="0 0 -1.41386"/>
      <parent link="26_Femur_FL_L"/>
      <child link="27_Tibia_FL_L"/>
      <axis xyz="0 0 1.0"/>
      <limit lower="-1.0" upper="1.0" effort="0.05" velocity="5.0"/>
    </joint>

    <joint name="28_Tarsus_FL_L" type="fixed">
      <origin xyz="0.00566 -1.29846 0.00154" rpy="0 0 -0.47093"/>
      <parent link="27_Tibia_FL_L"/>
      <child link="28_Tarsus_FL_L"/>
    </joint>

    <joint name="29_CT_FL_R" type="revolute">
      <origin xyz="0.02342 0.15725 -0.13854" rpy="-1.5708 -1.0472 1.5708"/>
      <parent link="02_Prothorax"/>
      <child link="29_CT_FL_R"/>
      <axis xyz="0 0 1.0"/>
      <limit lower="-1.0" upper="1.0" effort="0.05" velocity="5.0"/>
    </joint>

    <joint name="30_Femur_FL_R" type="revolute">
      <origin xyz="-0.10676 -0.00016 0.00476" rpy="1.5708 0.4962 0"/>
      <parent link="29_CT_FL_R"/>
      <child link="30_Femur_FL_R"/>
      <axis xyz="0 0 1.0"/>
      <limit lower="-1.0" upper="1.0" effort="0.05" velocity="5.0"/>
    </joint>

    <joint name="31_Tibia_FL_R" type="revolute">
      <origin xyz="-1.39582 -0.01768 0.00396" rpy="0 0 0"/>
      <parent link="30_Femur_FL_R"/>
      <child link="31_Tibia_FL_R"/>
      <axis xyz="0 0 1.0"/>
      <limit lower="-1.0" upper="1.0" effort="0.05" velocity="5.0"/>
    </joint>

    <joint name="32_Tarsus_FL_R" type="fixed">
      <origin xyz="-0.02218 -1.4161 -0.00491" rpy="0 0 0.57146"/>
      <parent link="31_Tibia_FL_R"/>
      <child link="32_Tarsus_FL_R"/>
    </joint>

    <material name="Textured_mesh_1">
      <color rgba="1 1 1 1.0"/>
    </material>

  </robot>
